Workbook

Sheet Instructions
B1: Project Planner - MS Project-compatible Excel template
B4: HOW IT WORKS
B5: 1. Settings | C5: Set project start, working week (Mon-Sun Yes/No), hours/day, status date, Gantt scale and sprint calendar. Add holidays on 'Holidays'.
B6: 2. Resources | C6: List people/roles with Max Units and hourly rate. They appear in the Resource dropdown on Tasks and in sprint capacity.
B7: 3. Tasks | C7: One row per task. Enter Level (1 = phase/summary, 2 = task, 3 = sub-task...), Task Name, Duration in working days (0 = milestone), and up to two predecessors by ID with link type (FS, SS, FF, SF) and lag in days (negative = lead). A row becomes a SUMMARY automatically when the rows beneath it have a higher level; its dates, work, cost and progress roll up.
B8: 4. Track progress | C8: Enter Actual Start, Actual Finish and % Complete. Forecast Start/Finish then use actuals and push every dependent task; Planned Start/Finish keep the original plan (= MS Project Baseline). Finish Variance and Status flag slippage.
B9: 5. Gantt | C9: Read-only view: grey line = planned dates, green = done, blue = remaining on track, orange = remaining but late vs plan, dark = summary, red border = status date. Change GanttStart / GanttPeriod (1 = days, 7 = weeks) on Settings to scroll or zoom.
B10: 6. Sprints | C10: Sprint calendar from Settings. Each task is tagged with the sprint its forecast start falls in. Work hours are prorated across sprints per resource, compared against capacity (Max Units x Hours/day x working days); over-allocations turn red.
B11: 7. Dashboard | C11: KPIs, status counts, upcoming milestones and sprint load vs capacity.
B13: CELL COLOURS
B14: Blue text | C14: Input - type here.
B15: Black text on grey | C15: Formula - do not overwrite. Summary rows grey-out inputs that are ignored.
B16: Dark blue header | C16: Input column. Dark grey header = calculated. Light grey header = helper column (hidden, grouped).
B18: RULES (same as MS Project)
B19: Task IDs | C19: ID = sequence of named rows. Inserting a row renumbers IDs below it (like MS Project) - re-check predecessor IDs after inserting or deleting rows. Easiest: add new tasks at the bottom of a phase and set Level.
B20: Outline levels | C20: Each row's Level may be at most 1 higher than the row above. A '?' in WBS (red) means a level jump.
B21: Predecessors | C21: Link detail tasks, not summaries, and never link a task to itself or its own summary (that creates a circular reference). Summary rows ignore Duration / Predecessors / Actuals - they roll up.
B22: Mode | C22: Auto = scheduled from predecessors, project start and 'Start No Earlier Than'. Manual = pinned to the date in 'Start No Earlier Than / Manual Start'.
B23: Rescheduling | C23: Settings > RescheduleAfterStatus = Yes moves incomplete work to after the status date (like MS Project 'Update Project'), so late tasks push successors.
B24: Capacity | C24: Rows provided: 200 tasks, 50 resources, 26 sprints, 100 holidays. To extend, copy the last formula row down and extend the named ranges in Name Manager.
B26: MOVING TO MICROSOFT PROJECT
B27: One-time setting | C27: MS Project > File > Options > Trust Center > Trust Center Settings > Legacy Formats > 'Allow loading files with legacy or non-default file formats'.
B28: Import | C28: In MS Project: File > Open > choose this .xlsx > Import Wizard > New map > 'As a new project' > tick Tasks (and Resources) > Tasks source worksheet = MSP_Tasks, Resources = MSP_Resources. Column headers already use MS Project field names, so the wizard maps them automatically.
B29: Tip: Start/Finish | C29: For auto-scheduled tasks map Duration + Predecessors (+ Constraint Type/Date) and set Start/Finish to '(not mapped)' - importing Start/Finish makes MS Project add fixed 'Start No Earlier Than' constraints. Map Baseline Start/Finish to keep the plan, and Actual Start/Finish/% Complete for progress.
B30: Rows | C30: MSP_Tasks contains 200 rows; blank rows import as blank tasks - delete them in MS Project or copy only the filled rows to a new sheet before importing.
B31: From MS Project to Excel | C31: MS Project > File > Save As > Excel Workbook > use the same field names, then paste Name / Outline Level / Duration / Predecessors etc. into the Tasks input columns (split '3FS+2d' into Pred ID, Type, Lag).
B33: NAMED RANGES (Formulas > Name Manager)
B34: Settings | C34: ProjectStart, StatusDate, StatusWorkday, WorkWeek, Holidays, HoursPerDay, DefaultUnits, RescheduleAfterStatus, GanttStart, GanttPeriod, Sprint1Start, SprintLength, SprintCount, SprintPrefix, SprintLastEnd
B35: Task columns | C35: tsk_ID, tsk_WBS, tsk_Level, tsk_Name, tsk_Duration, tsk_PlanStart, tsk_PlanFinish, tsk_ActStart, tsk_ActFinish, tsk_FcStart, tsk_FcFinish, tsk_Variance, tsk_Progress, tsk_Status, tsk_Resource, tsk_Work, tsk_Cost, tsk_Sprint, tsk_Predecessors, tsk_IsSummary, tsk_IsLeaf ... and hdr_* anchors used by OFFSET look-ups
B36: Resources / Sprints | C36: res_Name, res_MaxUnits, res_Rate, ... spr_Name, spr_Start, spr_End, spr_Capacity, spr_Work
B37: Key formulas | C37: Planned Start = WORKDAY.INTL(MAX(ProjectStart, StartNoEarlierThan, predecessor drivers) - 1, 1, WorkWeek, Holidays). Pred driver (FS) = WORKDAY.INTL(OFFSET(hdr_PlanFinish, MATCH(PredID, tsk_ID, 0), 0), 1 + Lag, WorkWeek, Holidays). Summary Start = MIN of its descendant block (OFFSET from the row, height = Descendant Count via COUNTIF(tsk_WBS, WBS & ".*")).

Sheet Dashboard
A1: =ProjectName&" - Dashboard" -> Customer Portal Implementation - Dashboard
A2: ="Project manager: "&ProjectManager&" Status date: "&TEXT(StatusDate,"ddd dd-mmm-yyyy") -> Project manager: Priya Sharma Status date: Sun 25-Oct-2026
B4: Key indicator | C4: Value | E4: Status (detail tasks) | F4: Count
B5: Planned start | C5: =MIN(tsk_PlanStart) -> 46272 | E5: Complete | F5: =COUNTIFS(tsk_Status,E5,tsk_IsLeaf,1) -> 9
B6: Planned finish | C6: =MAX(tsk_PlanFinish) -> 46393 | E6: In Progress | F6: =COUNTIFS(tsk_Status,E6,tsk_IsLeaf,1) -> 0
B7: Forecast finish | C7: =MAX(tsk_FcFinish) -> 46393 | E7: Behind | F7: =COUNTIFS(tsk_Status,E7,tsk_IsLeaf,1) -> 2
B8: Finish variance (work days) | C8: =IF(MAX(tsk_FcFinish)>=MAX(tsk_PlanFinish),NETWORKDAYS.INTL(MAX(tsk_PlanFinish),MAX(tsk_FcFinish),WorkWeek,Holidays)-1,1-NETWORKDAYS.INTL(MAX(tsk_FcFinish),MAX(tsk_PlanFinish),WorkWeek,Holidays)) -> 0 | E8: Late Start | F8: =COUNTIFS(tsk_Status,E8,tsk_IsLeaf,1) -> 1
B9: Overall progress (duration-weighted) | C9: =IFERROR(SUM(tsk_WtDone)/SUM(tsk_WtDur),0) -> 0.43417085 | E9: Not Started | F9: =COUNTIFS(tsk_Status,E9,tsk_IsLeaf,1) -> 11
B10: Planned progress by status date | C10: =IFERROR(SUMPRODUCT(tsk_WtDur*(tsk_PlanFinish<StatusDate))/SUM(tsk_WtDur),0) -> 0.45427136
B11: Detail tasks | C11: =SUM(tsk_IsLeaf) -> 23
B12: Milestones | C12: =SUMPRODUCT(tsk_IsLeaf*(tsk_Duration=0)*(tsk_Name<>"")) -> 5
B13: Total work (hrs) | C13: =SUMPRODUCT(tsk_Work,tsk_IsLeaf) -> 720
B14: Total cost | C14: =SUMPRODUCT(tsk_Cost,tsk_IsLeaf) -> 58040
B15: Current sprint | C15: =IF(OR(StatusDate<Sprint1Start,StatusDate>SprintLastEnd),"(outside sprint range)",INDEX(spr_Name,MATCH(StatusDate,spr_Start,1))) -> Sprint 4
B17: Next milestones (forecast) | C17: Forecast date
B18: =IFERROR(INDEX(tsk_Name,MATCH(SMALL(tsk_MilestoneKey,1),tsk_MilestoneKey,0)),"") -> Build complete | C18: =IFERROR(INDEX(tsk_FcFinish,MATCH(SMALL(tsk_MilestoneKey,1),tsk_MilestoneKey,0)),"") -> 46335
B19: =IFERROR(INDEX(tsk_Name,MATCH(SMALL(tsk_MilestoneKey,2),tsk_MilestoneKey,0)),"") -> Go-live | C19: =IFERROR(INDEX(tsk_FcFinish,MATCH(SMALL(tsk_MilestoneKey,2),tsk_MilestoneKey,0)),"") -> 46371
B20: =IFERROR(INDEX(tsk_Name,MATCH(SMALL(tsk_MilestoneKey,3),tsk_MilestoneKey,0)),"") -> Project closed | C20: =IFERROR(INDEX(tsk_FcFinish,MATCH(SMALL(tsk_MilestoneKey,3),tsk_MilestoneKey,0)),"") -> 46393
B21: =IFERROR(INDEX(tsk_Name,MATCH(SMALL(tsk_MilestoneKey,4),tsk_MilestoneKey,0)),"") | C21: =IFERROR(INDEX(tsk_FcFinish,MATCH(SMALL(tsk_MilestoneKey,4),tsk_MilestoneKey,0)),"")
B22: =IFERROR(INDEX(tsk_Name,MATCH(SMALL(tsk_MilestoneKey,5),tsk_MilestoneKey,0)),"") | C22: =IFERROR(INDEX(tsk_FcFinish,MATCH(SMALL(tsk_MilestoneKey,5),tsk_MilestoneKey,0)),"")

Sheet Settings
A1: Project Settings
A2: Blue = edit me. Grey = calculated. Column D shows the named range every formula uses.
B4: Setting | C4: Value | D4: Named range | E4: Notes
B5: Project name | C5: Customer Portal Implementation | D5: ProjectName | E5: Shown on every sheet title.
B6: Project manager | C6: Priya Sharma | D6: ProjectManager
B7: Project start date | C7: 46272 | D7: ProjectStart | E7: Tasks without predecessors start here (moved to the next working day if needed).
B8: Status date override | D8: StatusDateOverride | E8: Leave blank to use TODAY(). Type a date to report progress 'as of' that day.
B9: Status date (in use) | C9: =IF(StatusDateOverride="",TODAY(),StatusDateOverride) -> 46320 | D9: StatusDate | E9: Drives Status, the red 'today' line on the Gantt and rescheduling of late work.
B10: First working day on/after status date | C10: =WORKDAY.INTL(StatusDate-1,1,WorkWeek,Holidays) -> 46321 | D10: StatusWorkday
B11: Reschedule incomplete work after status date? | C11: Yes | D11: RescheduleAfterStatus | E11: Yes = like MS Project 'move incomplete parts after status date': unstarted tasks can't start before the status date and in-progress tasks finish their remaining duration after it, pushing all successors.
B12: Working hours per day | C12: 8 | D12: HoursPerDay | E12: Work (hrs) = Duration x Hours/day x Units.
B13: Default assignment units | C13: 1 | D13: DefaultUnits | E13: Used when a task has a resource but Units is blank. 100% = full time.
B14: Monday is a working day | C14: Yes | D14: WorkMon | E14: Working-week calendar (Yes/No). Feeds every WORKDAY / NETWORKDAYS formula.
B15: Tuesday is a working day | C15: Yes | D15: WorkTue
B16: Wednesday is a working day | C16: Yes | D16: WorkWed
B17: Thursday is a working day | C17: Yes | D17: WorkThu
B18: Friday is a working day | C18: Yes | D18: WorkFri
B19: Saturday is a working day | C19: No | D19: WorkSat
B20: Sunday is a working day | C20: No | D20: WorkSun
B21: Weekend mask (calculated) | C21: =IF(WorkMon="Yes","0","1")&IF(WorkTue="Yes","0","1")&IF(WorkWed="Yes","0","1")&IF(WorkThu="Yes","0","1")&IF(WorkFri="Yes","0","1")&IF(WorkSat="Yes","0","1")&IF(WorkSun="Yes","0","1") -> 0000011 | D21: WorkWeek | E21: 7-character Mon..Sun string used by WORKDAY.INTL (1 = non-working).
B22: Gantt timeline start | C22: =ProjectStart-WEEKDAY(ProjectStart,3) -> 46272 | D22: GanttStart | E22: Defaults to the Monday of the project start week. Overwrite with any date to scroll the timeline.
B23: Gantt days per column | C23: 1 | D23: GanttPeriod | E23: 1 = daily timeline, 7 = weekly timeline (150 columns either way).
B24: Sprint 1 start date | C24: =ProjectStart -> 46272 | D24: Sprint1Start | E24: Defaults to the project start. Overwrite to align with your sprint calendar.
B25: Sprint length (calendar days) | C25: 14 | D25: SprintLength | E25: 14 = two-week sprints.
B26: Number of sprints | C26: 12 | D26: SprintCount | E26: Up to 26. Tasks outside the sprint range are labelled 'Backlog'.
B27: Sprint name prefix | C27: Sprint | D27: SprintPrefix | E27: Sprint names = prefix & number.
B28: Last sprint end (calculated) | C28: =INDEX(spr_End,SprintCount) -> 46439 | D28: SprintLastEnd

Sheet Tasks
A1: =ProjectName&" - Task Entry" -> Customer Portal Implementation - Task Entry
A2: Type in BLUE columns only. Level = outline level (1 = phase, 2 = task, 3 = sub-task). Planned dates come from Duration + Predecessors; Forecast dates also use Actuals, so slips ripple to every successor.
A4: IDENTITY | E4: SCHEDULING INPUTS | N4: PLAN / ACTUAL / FORECAST | U4: PROGRESS | X4: RESOURCES & SPRINT | AE4: HELPER COLUMNS (hidden - click + above to show)
A5: ID | B5: WBS | C5: Level | D5: Task Name | E5: Mode | F5: Duration (work days) | G5: Pred 1 ID | H5: Type 1 | I5: Lag 1 (days) | J5: Pred 2 ID | K5: Type 2 | L5: Lag 2 (days) | M5: Start No Earlier Than / Manual Start | N5: Planned Start | O5: Planned Finish | P5: Actual Start | Q5: Actual Finish | R5: Forecast Start | S5: Forecast Finish | T5: Finish Variance (work days) | U5: % Complete (enter) | V5: Progress % (rolled up) | W5: Status | X5: Resource | Y5: Units | Z5: Work (hrs) | AA5: Cost | AB5: Sprint | AC5: Predecessors (MSP format) | AD5: Notes | AE5: Lvl (effective) | AF5: Row Index | AG5: Parent Row | AH5: Descendant Count | AI5: Is Summary | AJ5: Is Leaf | AK5: Pred1 Plan Driver | AL5: Pred2 Plan Driver | AM5: Pred1 Fcst Driver | AN5: Pred2 Fcst Driver | AO5: Fcst Start # (leaf) | AP5: Fcst Finish # (leaf) | AQ5: Work per Cal Day | AR5: Weight Dur | AS5: Weight Done | AT5: Pred1 Text | AU5: Pred2 Text | AV5: Open Milestone Key
A6: =IF($D6="","",COUNTA($D$6:$D6)) -> 1 | B6: =IF($D6="","",IF($AE6=1,COUNTIF($AE$6:$AE6,1)&"",IF($AG6=0,"?",OFFSET(hdr_WBS,$AG6-ROW(hdr_WBS),0)&"."&COUNTIF(INDEX($AE:$AE,$AG6+1):$AE6,$AE6)))) -> 1 | C6: 1 | D6: Initiation | E6: Auto | N6: =IF($D6="","",IF($AI6,MIN(OFFSET(hdr_PlanStart,$AF6+1,0,$AH6,1)),IF($E6="Manual",IF(N($M6)>0,$M6,ProjectStart),WORKDAY.INTL(MAX(ProjectStart,N($M6),$AK6,$AL6)-1,1,WorkWeek,Holidays)))) -> 46272 | O6: =IF($D6="","",IF($AI6,MAX(OFFSET(hdr_PlanFinish,$AF6+1,0,$AH6,1)),IF(N($F6)<=0,$N6,WORKDAY.INTL($N6,$F6-1,WorkWeek,Holidays)))) -> 46276 | R6: =IF($D6="","",IF($AI6,MIN(OFFSET(hdr_FcStart,$AF6+1,0,$AH6,1)),IF(N($P6)>0,$P6,IF($E6="Manual",IF(N($M6)>0,$M6,ProjectStart),WORKDAY.INTL(MAX(ProjectStart,N($M6),$AM6,$AN6,IF(RescheduleAfterStatus="Yes",StatusDate,0))-1,1,WorkWeek,Holidays))))) -> 46272 | S6: =IF($D6="","",IF($AI6,MAX(OFFSET(hdr_FcFinish,$AF6+1,0,$AH6,1)),IF(N($Q6)>0,$Q6,IF(N($F6)<=0,$R6,IF(AND(N($P6)>0,RescheduleAfterStatus="Yes"),MAX(WORKDAY.INTL($R6,$F6-1,WorkWeek,Holidays),WORKDAY.INTL(StatusWorkday,MAX(0,ROUNDUP($F6*(1-MIN(1,N($U6))),0)-1),WorkWeek,Holidays)),WORKDAY.INTL($R6,$F6-1,WorkWeek,Holidays)))))) -> 46279 | T6: =IF($D6="","",IF($S6>=$O6,NETWORKDAYS.INTL($O6,$S6,WorkWeek,Holidays)-1,1-NETWORKDAYS.INTL($S6,$O6,WorkWeek,Holidays))) -> 1 | V6: =IF($D6="","",IF($AI6,IFERROR(SUM(OFFSET(hdr_WtDone,$AF6+1,0,$AH6,1))/SUM(OFFSET(hdr_WtDur,$AF6+1,0,$AH6,1)),0),IF(N($Q6)>0,1,MIN(1,N($U6))))) -> 1 | W6: =IF($D6="","",IF($V6>=1,"Complete",IF(OR(N($P6)>0,$V6>0),IF($T6>0,"Behind","In Progress"),IF($N6<StatusDate,"Late Start","Not Started")))) -> Complete | Z6: =IF($D6="","",IF($AI6,SUMPRODUCT(OFFSET(hdr_Work,$AF6+1,0,$AH6,1),OFFSET(hdr_IsLeaf,$AF6+1,0,$AH6,1)),IF($X6="",0,N($F6)*HoursPerDay*IF($Y6="",DefaultUnits,$Y6)))) -> 40 | AA6: =IF($D6="","",IF($AI6,SUMPRODUCT(OFFSET(hdr_Cost,$AF6+1,0,$AH6,1),OFFSET(hdr_IsLeaf,$AF6+1,0,$AH6,1)),$Z6*IFERROR(INDEX(res_Rate,MATCH($X6,res_Name,0)),0))) -> 3400 | AB6: =IF(OR($D6="",$AI6),"",IF(OR($R6<Sprint1Start,$R6>SprintLastEnd),"Backlog",INDEX(spr_Name,MATCH($R6,spr_Start,1)))) | AC6: =IF($D6="","",$AT6&IF(AND($AT6<>"",$AU6<>""),",","")&$AU6) | AD6: Phase 1 - summary rows roll up dates, work, cost and progress automatically. | AE6: =IF($D6="","",MAX(1,N($C6))) -> 1 | AF6: =ROW()-ROW(hdr_ID) -> 1 | AG6: =IF(OR($D6="",$AE6<=1),0,IFERROR(LOOKUP(2,1/($AE$5:$AE5=$AE6-1),ROW($AE$5:$AE5)),0)) -> 0 | AH6: =IF($D6="",0,COUNTIF(tsk_WBS,$B6&".*")) -> 3 | AI6: =$AH6>0 -> TRUE | AJ6: =IF(AND($D6<>"",NOT($AI6)),1,0) -> 0 | AK6: =IF(OR(N($G6)=0,$AI6,$D6=""),0,IFERROR(CHOOSE(MATCH(IF($H6="","FS",$H6),{"FS","SS","FF","SF"},0),WORKDAY.INTL(OFFSET(hdr_PlanFinish,MATCH($G6,tsk_ID,0),0),IF(N($F6)=0,0,1)+N($I6),WorkWeek,Holidays),WORKDAY.INTL(OFFSET(hdr_PlanStart,MATCH($G6,tsk_ID,0),0),N($I6),WorkWeek,Holidays),WORKDAY.INTL(WORKDAY.INTL(OFFSET(hdr_PlanFinish,MATCH($G6,tsk_ID,0),0),N($I6),WorkWeek,Holidays),-MAX(0,N($F6)-1),WorkWeek,Holidays),WORKDAY.INTL(WORKDAY.INTL(OFFSET(hdr_PlanStart,MATCH($G6,tsk_ID,0),0),N($I6),WorkWeek,Holidays),-MAX(0,N($F6)-1),WorkWeek,Holidays)),0)) -> 0 | AL6: =IF(OR(N($J6)=0,$AI6,$D6=""),0,IFERROR(CHOOSE(MATCH(IF($K6="","FS",$K6),{"FS","SS","FF","SF"},0),WORKDAY.INTL(OFFSET(hdr_PlanFinish,MATCH($J6,tsk_ID,0),0),IF(N($F6)=0,0,1)+N($L6),WorkWeek,Holidays),WORKDAY.INTL(OFFSET(hdr_PlanStart,MATCH($J6,tsk_ID,0),0),N($L6),WorkWeek,Holidays),WORKDAY.INTL(WORKDAY.INTL(OFFSET(hdr_PlanFinish,MATCH($J6,tsk_ID,0),0),N($L6),WorkWeek,Holidays),-MAX(0,N($F6)-1),WorkWeek,Holidays),WORKDAY.INTL(WORKDAY.INTL(OFFSET(hdr_PlanStart,MATCH($J6,tsk_ID,0),0),N($L6),WorkWeek,Holidays),-MAX(0,N($F6)-1),WorkWeek,Holidays)),0)) -> 0 | AM6: =IF(OR(N($G6)=0,$AI6,$D6=""),0,IFERROR(CHOOSE(MATCH(IF($H6="","FS",$H6),{"FS","SS","FF","SF"},0),WORKDAY.INTL(OFFSET(hdr_FcFinish,MATCH($G6,tsk_ID,0),0),IF(N($F6)=0,0,1)+N($I6),WorkWeek,Holidays),WORKDAY.INTL(OFFSET(hdr_FcStart,MATCH($G6,tsk_ID,0),0),N($I6),WorkWeek,Holidays),WORKDAY.INTL(WORKDAY.INTL(OFFSET(hdr_FcFinish,MATCH($G6,tsk_ID,0),0),N($I6),WorkWeek,Holidays),-MAX(0,N($F6)-1),WorkWeek,Holidays),WORKDAY.INTL(WORKDAY.INTL(OFFSET(hdr_FcStart,MATCH($G6,tsk_ID,0),0),N($I6),WorkWeek,Holidays),-MAX(0,N($F6)-1),WorkWeek,Holidays)),0)) -> 0 | AN6: =IF(OR(N($J6)=0,$AI6,$D6=""),0,IFERROR(CHOOSE(MATCH(IF($K6="","FS",$K6),{"FS","SS","FF","SF"},0),WORKDAY.INTL(OFFSET(hdr_FcFinish,MATCH($J6,tsk_ID,0),0),IF(N($F6)=0,0,1)+N($L6),WorkWeek,Holidays),WORKDAY.INTL(OFFSET(hdr_FcStart,MATCH($J6,tsk_ID,0),0),N($L6),WorkWeek,Holidays),WORKDAY.INTL(WORKDAY.INTL(OFFSET(hdr_FcFinish,MATCH($J6,tsk_ID,0),0),N($L6),WorkWeek,Holidays),-MAX(0,N($F6)-1),WorkWeek,Holidays),WORKDAY.INTL(WORKDAY.INTL(OFFSET(hdr_FcStart,MATCH($J6,tsk_ID,0),0),N($L6),WorkWeek,Holidays),-MAX(0,N($F6)-1),WorkWeek,Holidays)),0)) -> 0 | AO6: =IF($AJ6=1,$R6,0) -> 0 | AP6: =IF($AJ6=1,$S6,0) -> 0 | AQ6: =IF(AND($AJ6=1,N($Z6)>0),$Z6/($AP6-$AO6+1),0) -> 0 | AR6: =IF($AJ6=1,MAX(N($F6),0.1),0) -> 0 | AS6: =IF($AJ6=1,$AR6*$V6,0) -> 0 | AT6: =IF(N($G6)=0,"",$G6&IF(AND(IF($H6="","FS",$H6)="FS",N($I6)=0),"",IF($H6="","FS",$H6)&IF(N($I6)=0,"",IF(N($I6)>0,"+","")&N($I6)&"d"))) | AU6: =IF(N($J6)=0,"",$J6&IF(AND(IF($K6="","FS",$K6)="FS",N($L6)=0),"",IF($K6="","FS",$K6)&IF(N($L6)=0,"",IF(N($L6)>0,"+","")&N($L6)&"d"))) | AV6: =IF(AND($AJ6=1,N($F6)=0,$V6<1),$S6+$AF6/100000,"")
A7: =IF($D7="","",COUNTA($D$6:$D7)) -> 2 | B7: =IF($D7="","",IF($AE7=1,COUNTIF($AE$6:$AE7,1)&"",IF($AG7=0,"?",OFFSET(hdr_WBS,$AG7-ROW(hdr_WBS),0)&"."&COUNTIF(INDEX($AE:$AE,$AG7+1):$AE7,$AE7)))) -> 1.1 | C7: 2 | D7: Project charter & scope statement | E7: Auto | F7: 3 | N7: =IF($D7="","",IF($AI7,MIN(OFFSET(hdr_PlanStart,$AF7+1,0,$AH7,1)),IF($E7="Manual",IF(N($M7)>0,$M7,ProjectStart),WORKDAY.INTL(MAX(ProjectStart,N($M7),$AK7,$AL7)-1,1,WorkWeek,Holidays)))) -> 46272 | O7: =IF($D7="","",IF($AI7,MAX(OFFSET(hdr_PlanFinish,$AF7+1,0,$AH7,1)),IF(N($F7)<=0,$N7,WORKDAY.INTL($N7,$F7-1,WorkWeek,Holidays)))) -> 46274 | P7: 46272 | Q7: 46275 | R7: =IF($D7="","",IF($AI7,MIN(OFFSET(hdr_FcStart,$AF7+1,0,$AH7,1)),IF(N($P7)>0,$P7,IF($E7="Manual",IF(N($M7)>0,$M7,ProjectStart),WORKDAY.INTL(MAX(ProjectStart,N($M7),$AM7,$AN7,IF(RescheduleAfterStatus="Yes",StatusDate,0))-1,1,WorkWeek,Holidays))))) -> 46272 | S7: =IF($D7="","",IF($AI7,MAX(OFFSET(hdr_FcFinish,$AF7+1,0,$AH7,1)),IF(N($Q7)>0,$Q7,IF(N($F7)<=0,$R7,IF(AND(N($P7)>0,RescheduleAfterStatus="Yes"),MAX(WORKDAY.INTL($R7,$F7-1,WorkWeek,Holidays),WORKDAY.INTL(StatusWorkday,MAX(0,ROUNDUP($F7*(1-MIN(1,N($U7))),0)-1),WorkWeek,Holidays)),WORKDAY.INTL($R7,$F7-1,WorkWeek,Holidays)))))) -> 46275 | T7: =IF($D7="","",IF($S7>=$O7,NETWORKDAYS.INTL($O7,$S7,WorkWeek,Holidays)-1,1-NETWORKDAYS.INTL($S7,$O7,WorkWeek,Holidays))) -> 1 | U7: 1 | V7: =IF($D7="","",IF($AI7,IFERROR(SUM(OFFSET(hdr_WtDone,$AF7+1,0,$AH7,1))/SUM(OFFSET(hdr_WtDur,$AF7+1,0,$AH7,1)),0),IF(N($Q7)>0,1,MIN(1,N($U7))))) -> 1 | W7: =IF($D7="","",IF($V7>=1,"Complete",IF(OR(N($P7)>0,$V7>0),IF($T7>0,"Behind","In Progress"),IF($N7<StatusDate,"Late Start","Not Started")))) -> Complete | X7: Priya Sharma | Z7: =IF($D7="","",IF($AI7,SUMPRODUCT(OFFSET(hdr_Work,$AF7+1,0,$AH7,1),OFFSET(hdr_IsLeaf,$AF7+1,0,$AH7,1)),IF($X7="",0,N($F7)*HoursPerDay*IF($Y7="",DefaultUnits,$Y7)))) -> 24 | AA7: =IF($D7="","",IF($AI7,SUMPRODUCT(OFFSET(hdr_Cost,$AF7+1,0,$AH7,1),OFFSET(hdr_IsLeaf,$AF7+1,0,$AH7,1)),$Z7*IFERROR(INDEX(res_Rate,MATCH($X7,res_Name,0)),0))) -> 2280 | AB7: =IF(OR($D7="",$AI7),"",IF(OR($R7<Sprint1Start,$R7>SprintLastEnd),"Backlog",INDEX(spr_Name,MATCH($R7,spr_Start,1)))) -> Sprint 1 | AC7: =IF($D7="","",$AT7&IF(AND($AT7<>"",$AU7<>""),",","")&$AU7) | AD7: Took 1 extra day for sponsor sign-off. | AE7: =IF($D7="","",MAX(1,N($C7))) -> 2 | AF7: =ROW()-ROW(hdr_ID) -> 2 | AG7: =IF(OR($D7="",$AE7<=1),0,IFERROR(LOOKUP(2,1/($AE$5:$AE6=$AE7-1),ROW($AE$5:$AE6)),0)) -> 6 | AH7: =IF($D7="",0,COUNTIF(tsk_WBS,$B7&".*")) -> 0 | AI7: =$AH7>0 -> FALSE | AJ7: =IF(AND($D7<>"",NOT($AI7)),1,0) -> 1 | AK7: =IF(OR(N($G7)=0,$AI7,$D7=""),0,IFERROR(CHOOSE(MATCH(IF($H7="","FS",$H7),{"FS","SS","FF","SF"},0),WORKDAY.INTL(OFFSET(hdr_PlanFinish,MATCH($G7,tsk_ID,0),0),IF(N($F7)=0,0,1)+N($I7),WorkWeek,Holidays),WORKDAY.INTL(OFFSET(hdr_PlanStart,MATCH($G7,tsk_ID,0),0),N($I7),WorkWeek,Holidays),WORKDAY.INTL(WORKDAY.INTL(OFFSET(hdr_PlanFinish,MATCH($G7,tsk_ID,0),0),N($I7),WorkWeek,Holidays),-MAX(0,N($F7)-1),WorkWeek,Holidays),WORKDAY.INTL(WORKDAY.INTL(OFFSET(hdr_PlanStart,MATCH($G7,tsk_ID,0),0),N($I7),WorkWeek,Holidays),-MAX(0,N($F7)-1),WorkWeek,Holidays)),0)) -> 0 | AL7: =IF(OR(N($J7)=0,$AI7,$D7=""),0,IFERROR(CHOOSE(MATCH(IF($K7="","FS",$K7),{"FS","SS","FF","SF"},0),WORKDAY.INTL(OFFSET(hdr_PlanFinish,MATCH($J7,tsk_ID,0),0),IF(N($F7)=0,0,1)+N($L7),WorkWeek,Holidays),WORKDAY.INTL(OFFSET(hdr_PlanStart,MATCH($J7,tsk_ID,0),0),N($L7),WorkWeek,Holidays),WORKDAY.INTL(WORKDAY.INTL(OFFSET(hdr_PlanFinish,MATCH($J7,tsk_ID,0),0),N($L7),WorkWeek,Holidays),-MAX(0,N($F7)-1),WorkWeek,Holidays),WORKDAY.INTL(WORKDAY.INTL(OFFSET(hdr_PlanStart,MATCH($J7,tsk_ID,0),0),N($L7),WorkWeek,Holidays),-MAX(0,N($F7)-1),WorkWeek,Holidays)),0)) -> 0 | AM7: =IF(OR(N($G7)=0,$AI7,$D7=""),0,IFERROR(CHOOSE(MATCH(IF($H7="","FS",$H7),{"FS","SS","FF","SF"},0),WORKDAY.INTL(OFFSET(hdr_FcFinish,MATCH($G7,tsk_ID,0),0),IF(N($F7)=0,0,1)+N($I7),WorkWeek,Holidays),WORKDAY.INTL(OFFSET(hdr_FcStart,MATCH($G7,tsk_ID,0),0),N($I7),WorkWeek,Holidays),WORKDAY.INTL(WORKDAY.INTL(OFFSET(hdr_FcFinish,MATCH($G7,tsk_ID,0),0),N($I7),WorkWeek,Holidays),-MAX(0,N($F7)-1),WorkWeek,Holidays),WORKDAY.INTL(WORKDAY.INTL(OFFSET(hdr_FcStart,MATCH($G7,tsk_ID,0),0),N($I7),WorkWeek,Holidays),-MAX(0,N($F7)-1),WorkWeek,Holidays)),0)) -> 0 | AN7: =IF(OR(N($J7)=0,$AI7,$D7=""),0,IFERROR(CHOOSE(MATCH(IF($K7="","FS",$K7),{"FS","SS","FF","SF"},0),WORKDAY.INTL(OFFSET(hdr_FcFinish,MATCH($J7,tsk_ID,0),0),IF(N($F7)=0,0,1)+N($L7),WorkWeek,Holidays),WORKDAY.INTL(OFFSET(hdr_FcStart,MATCH($J7,tsk_ID,0),0),N($L7),WorkWeek,Holidays),WORKDAY.INTL(WORKDAY.INTL(OFFSET(hdr_FcFinish,MATCH($J7,tsk_ID,0),0),N($L7),WorkWeek,Holidays),-MAX(0,N($F7)-1),WorkWeek,Holidays),WORKDAY.INTL(WORKDAY.INTL(OFFSET(hdr_FcStart,MATCH($J7,tsk_ID,0),0),N($L7),WorkWeek,Holidays),-MAX(0,N($F7)-1),WorkWeek,Holidays)),0)) -> 0 | AO7: =IF($AJ7=1,$R7,0) -> 46272 | AP7: =IF($AJ7=1,$S7,0) -> 46275 | AQ7: =IF(AND($AJ7=1,N($Z7)>0),$Z7/($AP7-$AO7+1),0) -> 6 | AR7: =IF($AJ7=1,MAX(N($F7),0.1),0) -> 3 | AS7: =IF($AJ7=1,$AR7*$V7,0) -> 3 | AT7: =IF(N($G7)=0,"",$G7&IF(AND(IF($H7="","FS",$H7)="FS",N($I7)=0),"",IF($H7="","FS",$H7)&IF(N($I7)=0,"",IF(N($I7)>0,"+","")&N($I7)&"d"))) | AU7: =IF(N($J7)=0,"",$J7&IF(AND(IF($K7="","FS",$K7)="FS",N($L7)=0),"",IF($K7="","FS",$K7)&IF(N($L7)=0,"",IF(N($L7)>0,"+","")&N($L7)&"d"))) | AV7: =IF(AND($AJ7=1,N($F7)=0,$V7<1),$S7+$AF7/100000,"")
A8: =IF($D8="","",COUNTA($D$6:$D8)) -> 3 | B8: =IF($D8="","",IF($AE8=1,COUNTIF($AE$6:$AE8,1)&"",IF($AG8=0,"?",OFFSET(hdr_WBS,$AG8-ROW(hdr_WBS),0)&"."&COUNTIF(INDEX($AE:$AE,$AG8+1):$AE8,$AE8)))) -> 1.2 | C8: 2 | D8: Stakeholder kickoff workshop | E8: Auto | F8: 2 | G8: 2 | H8: FS | N8: =IF($D8="","",IF($AI8,MIN(OFFSET(hdr_PlanStart,$AF8+1,0,$AH8,1)),IF($E8="Manual",IF(N($M8)>0,$M8,ProjectStart),WORKDAY.INTL(MAX(ProjectStart,N($M8),$AK8,$AL8)-1,1,WorkWeek,Holidays)))) -> 46275 | O8: =IF($D8="","",IF($AI8,MAX(OFFSET(hdr_PlanFinish,$AF8+1,0,$AH8,1)),IF(N($F8)<=0,$N8,WORKDAY.INTL($N8,$F8-1,WorkWeek,Holidays)))) -> 46276 | P8: 46276 | Q8: 46279 | R8: =IF($D8="","",IF($AI8,MIN(OFFSET(hdr_FcStart,$AF8+1,0,$AH8,1)),IF(N($P8)>0,$P8,IF($E8="Manual",IF(N($M8)>0,$M8,ProjectStart),WORKDAY.INTL(MAX(ProjectStart,N($M8),$AM8,$AN8,IF(RescheduleAfterStatus="Yes",StatusDate,0))-1,1,WorkWeek,Holidays))))) -> 46276 | S8: =IF($D8="","",IF($AI8,MAX(OFFSET(hdr_FcFinish,$AF8+1,0,$AH8,1)),IF(N($Q8)>0,$Q8,IF(N($F8)<=0,$R8,IF(AND(N($P8)>0,RescheduleAfterStatus="Yes"),MAX(WORKDAY.INTL($R8,$F8-1,WorkWeek,Holidays),WORKDAY.INTL(StatusWorkday,MAX(0,ROUNDUP($F8*(1-MIN(1,N($U8))),0)-1),WorkWeek,Holidays)),WORKDAY.INTL($R8,$F8-1,WorkWeek,Holidays)))))) -> 46279 | T8: =IF($D8="","",IF($S8>=$O8,NETWORKDAYS.INTL($O8,$S8,WorkWeek,Holidays)-1,1-NETWORKDAYS.INTL($S8,$O8,WorkWeek,Holidays))) -> 1 | U8: 1 | V8: =IF($D8="","",IF($AI8,IFERROR(SUM(OFFSET(hdr_WtDone,$AF8+1,0,$AH8,1))/SUM(OFFSET(hdr_WtDur,$AF8+1,0,$AH8,1)),0),IF(N($Q8)>0,1,MIN(1,N($U8))))) -> 1 | W8: =IF($D8="","",IF($V8>=1,"Complete",IF(OR(N($P8)>0,$V8>0),IF($T8>0,"Behind","In Progress"),IF($N8<StatusDate,"Late Start","Not Started")))) -> Complete | X8: Morgan Patel | Z8: =IF($D8="","",IF($AI8,SUMPRODUCT(OFFSET(hdr_Work,$AF8+1,0,$AH8,1),OFFSET(hdr_IsLeaf,$AF8+1,0,$AH8,1)),IF($X8="",0,N($F8)*HoursPerDay*IF($Y8="",DefaultUnits,$Y8)))) -> 16 | AA8: =IF($D8="","",IF($AI8,SUMPRODUCT(OFFSET(hdr_Cost,$AF8+1,0,$AH8,1),OFFSET(hdr_IsLeaf,$AF8+1,0,$AH8,1)),$Z8*IFERROR(INDEX(res_Rate,MATCH($X8,res_Name,0)),0))) -> 1120 | AB8: =IF(OR($D8="",$AI8),"",IF(OR($R8<Sprint1Start,$R8>SprintLastEnd),"Backlog",INDEX(spr_Name,MATCH($R8,spr_Start,1)))) -> Sprint 1 | AC8: =IF($D8="","",$AT8&IF(AND($AT8<>"",$AU8<>""),",","")&$AU8) -> 2 | AE8: =IF($D8="","",MAX(1,N($C8))) -> 2 | AF8: =ROW()-ROW(hdr_ID) -> 3 | AG8: =IF(OR($D8="",$AE8<=1),0,IFERROR(LOOKUP(2,1/($AE$5:$AE7=$AE8-1),ROW($AE$5:$AE7)),0)) -> 6 | AH8: =IF($D8="",0,COUNTIF(tsk_WBS,$B8&".*")) -> 0 | AI8: =$AH8>0 -> FALSE | AJ8: =IF(AND($D8<>"",NOT($AI8)),1,0) -> 1 | AK8: =IF(OR(N($G8)=0,$AI8,$D8=""),0,IFERROR(CHOOSE(MATCH(IF($H8="","FS",$H8),{"FS","SS","FF","SF"},0),WORKDAY.INTL(OFFSET(hdr_PlanFinish,MATCH($G8,tsk_ID,0),0),IF(N($F8)=0,0,1)+N($I8),WorkWeek,Holidays),WORKDAY.INTL(OFFSET(hdr_PlanStart,MATCH($G8,tsk_ID,0),0),N($I8),WorkWeek,Holidays),WORKDAY.INTL(WORKDAY.INTL(OFFSET(hdr_PlanFinish,MATCH($G8,tsk_ID,0),0),N($I8),WorkWeek,Holidays),-MAX(0,N($F8)-1),WorkWeek,Holidays),WORKDAY.INTL(WORKDAY.INTL(OFFSET(hdr_PlanStart,MATCH($G8,tsk_ID,0),0),N($I8),WorkWeek,Holidays),-MAX(0,N($F8)-1),WorkWeek,Holidays)),0)) -> 46275 | AL8: =IF(OR(N($J8)=0,$AI8,$D8=""),0,IFERROR(CHOOSE(MATCH(IF($K8="","FS",$K8),{"FS","SS","FF","SF"},0),WORKDAY.INTL(OFFSET(hdr_PlanFinish,MATCH($J8,tsk_ID,0),0),IF(N($F8)=0,0,1)+N($L8),WorkWeek,Holidays),WORKDAY.INTL(OFFSET(hdr_PlanStart,MATCH($J8,tsk_ID,0),0),N($L8),WorkWeek,Holidays),WORKDAY.INTL(WORKDAY.INTL(OFFSET(hdr_PlanFinish,MATCH($J8,tsk_ID,0),0),N($L8),WorkWeek,Holidays),-MAX(0,N($F8)-1),WorkWeek,Holidays),WORKDAY.INTL(WORKDAY.INTL(OFFSET(hdr_PlanStart,MATCH($J8,tsk_ID,0),0),N($L8),WorkWeek,Holidays),-MAX(0,N($F8)-1),WorkWeek,Holidays)),0)) -> 0 | AM8: =IF(OR(N($G8)=0,$AI8,$D8=""),0,IFERROR(CHOOSE(MATCH(IF($H8="","FS",$H8),{"FS","SS","FF","SF"},0),WORKDAY.INTL(OFFSET(hdr_FcFinish,MATCH($G8,tsk_ID,0),0),IF(N($F8)=0,0,1)+N($I8),WorkWeek,Holidays),WORKDAY.INTL(OFFSET(hdr_FcStart,MATCH($G8,tsk_ID,0),0),N($I8),WorkWeek,Holidays),WORKDAY.INTL(WORKDAY.INTL(OFFSET(hdr_FcFinish,MATCH($G8,tsk_ID,0),0),N($I8),WorkWeek,Holidays),-MAX(0,N($F8)-1),WorkWeek,Holidays),WORKDAY.INTL(WORKDAY.INTL(OFFSET(hdr_FcStart,MATCH($G8,tsk_ID,0),0),N($I8),WorkWeek,Holidays),-MAX(0,N($F8)-1),WorkWeek,Holidays)),0)) -> 46276 | AN8: =IF(OR(N($J8)=0,$AI8,$D8=""),0,IFERROR(CHOOSE(MATCH(IF($K8="","FS",$K8),{"FS","SS","FF","SF"},0),WORKDAY.INTL(OFFSET(hdr_FcFinish,MATCH($J8,tsk_ID,0),0),IF(N($F8)=0,0,1)+N($L8),WorkWeek,Holidays),WORKDAY.INTL(OFFSET(hdr_FcStart,MATCH($J8,tsk_ID,0),0),N($L8),WorkWeek,Holidays),WORKDAY.INTL(WORKDAY.INTL(OFFSET(hdr_FcFinish,MATCH($J8,tsk_ID,0),0),N($L8),WorkWeek,Holidays),-MAX(0,N($F8)-1),WorkWeek,Holidays),WORKDAY.INTL(WORKDAY.INTL(OFFSET(hdr_FcStart,MATCH($J8,tsk_ID,0),0),N($L8),WorkWeek,Holidays),-MAX(0,N($F8)-1),WorkWeek,Holidays)),0)) -> 0 | AO8: =IF($AJ8=1,$R8,0) -> 46276 | AP8: =IF($AJ8=1,$S8,0) -> 46279 | AQ8: =IF(AND($AJ8=1,N($Z8)>0),$Z8/($AP8-$AO8+1),0) -> 4 | AR8: =IF($AJ8=1,MAX(N($F8),0.1),0) -> 2 | AS8: =IF($AJ8=1,$AR8*$V8,0) -> 2 | AT8: =IF(N($G8)=0,"",$G8&IF(AND(IF($H8="","FS",$H8)="FS",N($I8)=0),"",IF($H8="","FS",$H8)&IF(N($I8)=0,"",IF(N($I8)>0,"+","")&N($I8)&"d"))) -> 2 | AU8: =IF(N($J8)=0,"",$J8&IF(AND(IF($K8="","FS",$K8)="FS",N($L8)=0),"",IF($K8="","FS",$K8)&IF(N($L8)=0,"",IF(N($L8)>0,"+","")&N($L8)&"d"))) | AV8: =IF(AND($AJ8=1,N($F8)=0,$V8<1),$S8+$AF8/100000,"")
A9: =IF($D9="","",COUNTA($D$6:$D9)) -> 4 | B9: =IF($D9="","",IF($AE9=1,COUNTIF($AE$6:$AE9,1)&"",IF($AG9=0,"?",OFFSET(hdr_WBS,$AG9-ROW(hdr_WBS),0)&"."&COUNTIF(INDEX($AE:$AE,$AG9+1):$AE9,$AE9)))) -> 1.3 | C9: 2 | D9: Kickoff complete | E9: Auto | F9: 0 | G9: 3 | H9: FS | N9: =IF($D9="","",IF($AI9,MIN(OFFSET(hdr_PlanStart,$AF9+1,0,$AH9,1)),IF($E9="Manual",IF(N($M9)>0,$M9,ProjectStart),WORKDAY.INTL(MAX(ProjectStart,N($M9),$AK9,$AL9)-1,1,WorkWeek,Holidays)))) -> 46276 | O9: =IF($D9="","",IF($AI9,MAX(OFFSET(hdr_PlanFinish,$AF9+1,0,$AH9,1)),IF(N($F9)<=0,$N9,WORKDAY.INTL($N9,$F9-1,WorkWeek,Holidays)))) -> 46276 | P9: 46279 | Q9: 46279 | R9: =IF($D9="","",IF($AI9,MIN(OFFSET(hdr_FcStart,$AF9+1,0,$AH9,1)),IF(N($P9)>0,$P9,IF($E9="Manual",IF(N($M9)>0,$M9,ProjectStart),WORKDAY.INTL(MAX(ProjectStart,N($M9),$AM9,$AN9,IF(RescheduleAfterStatus="Yes",StatusDate,0))-1,1,WorkWeek,Holidays))))) -> 46279 | S9: =IF($D9="","",IF($AI9,MAX(OFFSET(hdr_FcFinish,$AF9+1,0,$AH9,1)),IF(N($Q9)>0,$Q9,IF(N($F9)<=0,$R9,IF(AND(N($P9)>0,RescheduleAfterStatus="Yes"),MAX(WORKDAY.INTL($R9,$F9-1,WorkWeek,Holidays),WORKDAY.INTL(StatusWorkday,MAX(0,ROUNDUP($F9*(1-MIN(1,N($U9))),0)-1),WorkWeek,Holidays)),WORKDAY.INTL($R9,$F9-1,WorkWeek,Holidays)))))) -> 46279 | T9: =IF($D9="","",IF($S9>=$O9,NETWORKDAYS.INTL($O9,$S9,WorkWeek,Holidays)-1,1-NETWORKDAYS.INTL($S9,$O9,WorkWeek,Holidays))) -> 1 | U9: 1 | V9: =IF($D9="","",IF($AI9,IFERROR(SUM(OFFSET(hdr_WtDone,$AF9+1,0,$AH9,1))/SUM(OFFSET(hdr_WtDur,$AF9+1,0,$AH9,1)),0),IF(N($Q9)>0,1,MIN(1,N($U9))))) -> 1 | W9: =IF($D9="","",IF($V9>=1,"Complete",IF(OR(N($P9)>0,$V9>0),IF($T9>0,"Behind","In Progress"),IF($N9<StatusDate,"Late Start","Not Started")))) -> Complete | Z9: =IF($D9="","",IF($AI9,SUMPRODUCT(OFFSET(hdr_Work,$AF9+1,0,$AH9,1),OFFSET(hdr_IsLeaf,$AF9+1,0,$AH9,1)),IF($X9="",0,N($F9)*HoursPerDay*IF($Y9="",DefaultUnits,$Y9)))) -> 0 | AA9: =IF($D9="","",IF($AI9,SUMPRODUCT(OFFSET(hdr_Cost,$AF9+1,0,$AH9,1),OFFSET(hdr_IsLeaf,$AF9+1,0,$AH9,1)),$Z9*IFERROR(INDEX(res_Rate,MATCH($X9,res_Name,0)),0))) -> 0 | AB9: =IF(OR($D9="",$AI9),"",IF(OR($R9<Sprint1Start,$R9>SprintLastEnd),"Backlog",INDEX(spr_Name,MATCH($R9,spr_Start,1)))) -> Sprint 1 | AC9: =IF($D9="","",$AT9&IF(AND($AT9<>"",$AU9<>""),",","")&$AU9) -> 3 | AD9: Milestone (Duration 0). | AE9: =IF($D9="","",MAX(1,N($C9))) -> 2 | AF9: =ROW()-ROW(hdr_ID) -> 4 | AG9: =IF(OR($D9="",$AE9<=1),0,IFERROR(LOOKUP(2,1/($AE$5:$AE8=$AE9-1),ROW($AE$5:$AE8)),0)) -> 6 | AH9: =IF($D9="",0,COUNTIF(tsk_WBS,$B9&".*")) -> 0 | AI9: =$AH9>0 -> FALSE | AJ9: =IF(AND($D9<>"",NOT($AI9)),1,0) -> 1 | AK9: =IF(OR(N($G9)=0,$AI9,$D9=""),0,IFERROR(CHOOSE(MATCH(IF($H9="","FS",$H9),{"FS","SS","FF","SF"},0),WORKDAY.INTL(OFFSET(hdr_PlanFinish,MATCH($G9,tsk_ID,0),0),IF(N($F9)=0,0,1)+N($I9),WorkWeek,Holidays),WORKDAY.INTL(OFFSET(hdr_PlanStart,MATCH($G9,tsk_ID,0),0),N($I9),WorkWeek,Holidays),WORKDAY.INTL(WORKDAY.INTL(OFFSET(hdr_PlanFinish,MATCH($G9,tsk_ID,0),0),N($I9),WorkWeek,Holidays),-MAX(0,N($F9)-1),WorkWeek,Holidays),WORKDAY.INTL(WORKDAY.INTL(OFFSET(hdr_PlanStart,MATCH($G9,tsk_ID,0),0),N($I9),WorkWeek,Holidays),-MAX(0,N($F9)-1),WorkWeek,Holidays)),0)) -> 46276 | AL9: =IF(OR(N($J9)=0,$AI9,$D9=""),0,IFERROR(CHOOSE(MATCH(IF($K9="","FS",$K9),{"FS","SS","FF","SF"},0),WORKDAY.INTL(OFFSET(hdr_PlanFinish,MATCH($J9,tsk_ID,0),0),IF(N($F9)=0,0,1)+N($L9),WorkWeek,Holidays),WORKDAY.INTL(OFFSET(hdr_PlanStart,MATCH($J9,tsk_ID,0),0),N($L9),WorkWeek,Holidays),WORKDAY.INTL(WORKDAY.INTL(OFFSET(hdr_PlanFinish,MATCH($J9,tsk_ID,0),0),N($L9),WorkWeek,Holidays),-MAX(0,N($F9)-1),WorkWeek,Holidays),WORKDAY.INTL(WORKDAY.INTL(OFFSET(hdr_PlanStart,MATCH($J9,tsk_ID,0),0),N($L9),WorkWeek,Holidays),-MAX(0,N($F9)-1),WorkWeek,Holidays)),0)) -> 0 | AM9: =IF(OR(N($G9)=0,$AI9,$D9=""),0,IFERROR(CHOOSE(MATCH(IF($H9="","FS",$H9),{"FS","SS","FF","SF"},0),WORKDAY.INTL(OFFSET(hdr_FcFinish,MATCH($G9,tsk_ID,0),0),IF(N($F9)=0,0,1)+N($I9),WorkWeek,Holidays),WORKDAY.INTL(OFFSET(hdr_FcStart,MATCH($G9,tsk_ID,0),0),N($I9),WorkWeek,Holidays),WORKDAY.INTL(WORKDAY.INTL(OFFSET(hdr_FcFinish,MATCH($G9,tsk_ID,0),0),N($I9),WorkWeek,Holidays),-MAX(0,N($F9)-1),WorkWeek,Holidays),WORKDAY.INTL(WORKDAY.INTL(OFFSET(hdr_FcStart,MATCH($G9,tsk_ID,0),0),N($I9),WorkWeek,Holidays),-MAX(0,N($F9)-1),WorkWeek,Holidays)),0)) -> 46279 | AN9: =IF(OR(N($J9)=0,$AI9,$D9=""),0,IFERROR(CHOOSE(MATCH(IF($K9="","FS",$K9),{"FS","SS","FF","SF"},0),WORKDAY.INTL(OFFSET(hdr_FcFinish,MATCH($J9,tsk_ID,0),0),IF(N($F9)=0,0,1)+N($L9),WorkWeek,Holidays),WORKDAY.INTL(OFFSET(hdr_FcStart,MATCH($J9,tsk_ID,0),0),N($L9),WorkWeek,Holidays),WORKDAY.INTL(WORKDAY.INTL(OFFSET(hdr_FcFinish,MATCH($J9,tsk_ID,0),0),N($L9),WorkWeek,Holidays),-MAX(0,N($F9)-1),WorkWeek,Holidays),WORKDAY.INTL(WORKDAY.INTL(OFFSET(hdr_FcStart,MATCH($J9,tsk_ID,0),0),N($L9),WorkWeek,Holidays),-MAX(0,N($F9)-1),WorkWeek,Holidays)),0)) -> 0 | AO9: =IF($AJ9=1,$R9,0) -> 46279 | AP9: =IF($AJ9=1,$S9,0) -> 46279 | AQ9: =IF(AND($AJ9=1,N($Z9)>0),$Z9/($AP9-$AO9+1),0) -> 0 | AR9: =IF($AJ9=1,MAX(N($F9),0.1),0) -> 0.1 | AS9: =IF($AJ9=1,$AR9*$V9,0) -> 0.1 | AT9: =IF(N($G9)=0,"",$G9&IF(AND(IF($H9="","FS",$H9)="FS",N($I9)=0),"",IF($H9="","FS",$H9)&IF(N($I9)=0,"",IF(N($I9)>0,"+","")&N($I9)&"d"))) -> 3 | AU9: =IF(N($J9)=0,"",$J9&IF(AND(IF($K9="","FS",$K9)="FS",N($L9)=0),"",IF($K9="","FS",$K9)&IF(N($L9)=0,"",IF(N($L9)>0,"+","")&N($L9)&"d"))) | AV9: =IF(AND($AJ9=1,N($F9)=0,$V9<1),$S9+$AF9/100000,"")
A10: =IF($D10="","",COUNTA($D$6:$D10)) -> 5 | B10: =IF($D10="","",IF($AE10=1,COUNTIF($AE$6:$AE10,1)&"",IF($AG10=0,"?",OFFSET(hdr_WBS,$AG10-ROW(hdr_WBS),0)&"."&COUNTIF(INDEX($AE:$AE,$AG10+1):$AE10,$AE10)))) -> 2 | C10: 1 | D10: Requirements & Design | E10: Auto | N10: =IF($D10="","",IF($AI10,MIN(OFFSET(hdr_PlanStart,$AF10+1,0,$AH10,1)),IF($E10="Manual",IF(N($M10)>0,$M10,ProjectStart),WORKDAY.INTL(MAX(ProjectStart,N($M10),$AK10,$AL10)-1,1,WorkWeek,Holidays)))) -> 46279 | O10: =IF($D10="","",IF($AI10,MAX(OFFSET(hdr_PlanFinish,$AF10+1,0,$AH10,1)),IF(N($F10)<=0,$N10,WORKDAY.INTL($N10,$F10-1,WorkWeek,Holidays)))) -> 46296 | R10: =IF($D10="","",IF($AI10,MIN(OFFSET(hdr_FcStart,$AF10+1,0,$AH10,1)),IF(N($P10)>0,$P10,IF($E10="Manual",IF(N($M10)>0,$M10,ProjectStart),WORKDAY.INTL(MAX(ProjectStart,N($M10),$AM10,$AN10,IF(RescheduleAfterStatus="Yes",StatusDate,0))-1,1,WorkWeek,Holidays))))) -> 46280 | S10: =IF($D10="","",IF($AI10,MAX(OFFSET(hdr_FcFinish,$AF10+1,0,$AH10,1)),IF(N($Q10)>0,$Q10,IF(N($F10)<=0,$R10,IF(AND(N($P10)>0,RescheduleAfterStatus="Yes"),MAX(WORKDAY.INTL($R10,$F10-1,WorkWeek,Holidays),WORKDAY.INTL(StatusWorkday,MAX(0,ROUNDUP($F10*(1-MIN(1,N($U10))),0)-1),WorkWeek,Holidays)),WORKDAY.INTL($R10,$F10-1,WorkWeek,Holidays)))))) -> 46301 | T10: =IF($D10="","",IF($S10>=$O10,NETWORKDAYS.INTL($O10,$S10,WorkWeek,Holidays)-1,1-NETWORKDAYS.INTL($S10,$O10,WorkWeek,Holidays))) -> 3 | V10: =IF($D10="","",IF($AI10,IFERROR(SUM(OFFSET(hdr_WtDone,$AF10+1,0,$AH10,1))/SUM(OFFSET(hdr_WtDur,$AF10+1,0,$AH10,1)),0),IF(N($Q10)>0,1,MIN(1,N($U10))))) -> 1 | W10: =IF($D10="","",IF($V10>=1,"Complete",IF(OR(N($P10)>0,$V10>0),IF($T10>0,"Behind","In Progress"),IF($N10<StatusDate,"Late Start","Not Started")))) -> Complete | Z10: =IF($D10="","",IF($AI10,SUMPRODUCT(OFFSET(hdr_Work,$AF10+1,0,$AH10,1),OFFSET(hdr_IsLeaf,$AF10+1,0,$AH10,1)),IF($X10="",0,N($F10)*HoursPerDay*IF($Y10="",DefaultUnits,$Y10)))) -> 152 | AA10: =IF($D10="","",IF($AI10,SUMPRODUCT(OFFSET(hdr_Cost,$AF10+1,0,$AH10,1),OFFSET(hdr_IsLeaf,$AF10+1,0,$AH10,1)),$Z10*IFERROR(INDEX(res_Rate,MATCH($X10,res_Name,0)),0))) -> 12480 | AB10: =IF(OR($D10="",$AI10),"",IF(OR($R10<Sprint1Start,$R10>SprintLastEnd),"Backlog",INDEX(spr_Name,MATCH($R10,spr_Start,1)))) | AC10: =IF($D10="","",$AT10&IF(AND($AT10<>"",$AU10<>""),",","")&$AU10) | AE10: =IF($D10="","",MAX(1,N($C10))) -> 1 | AF10: =ROW()-ROW(hdr_ID) -> 5 | AG10: =IF(OR($D10="",$AE10<=1),0,IFERROR(LOOKUP(2,1/($AE$5:$AE9=$AE10-1),ROW($AE$5:$AE9)),0)) -> 0 | AH10: =IF($D10="",0,COUNTIF(tsk_WBS,$B10&".*")) -> 4 | AI10: =$AH10>0 -> TRUE | AJ10: =IF(AND($D10<>"",NOT($AI10)),1,0) -> 0 | AK10: =IF(OR(N($G10)=0,$AI10,$D10=""),0,IFERROR(CHOOSE(MATCH(IF($H10="","FS",$H10),{"FS","SS","FF","SF"},0),WORKDAY.INTL(OFFSET(hdr_PlanFinish,MATCH($G10,tsk_ID,0),0),IF(N($F10)=0,0,1)+N($I10),WorkWeek,Holidays),WORKDAY.INTL(OFFSET(hdr_PlanStart,MATCH($G10,tsk_ID,0),0),N($I10),WorkWeek,Holidays),WORKDAY.INTL(WORKDAY.INTL(OFFSET(hdr_PlanFinish,MATCH($G10,tsk_ID,0),0),N($I10),WorkWeek,Holidays),-MAX(0,N($F10)-1),WorkWeek,Holidays),WORKDAY.INTL(WORKDAY.INTL(OFFSET(hdr_PlanStart,MATCH($G10,tsk_ID,0),0),N($I10),WorkWeek,Holidays),-MAX(0,N($F10)-1),WorkWeek,Holidays)),0)) -> 0 | AL10: =IF(OR(N($J10)=0,$AI10,$D10=""),0,IFERROR(CHOOSE(MATCH(IF($K10="","FS",$K10),{"FS","SS","FF","SF"},0),WORKDAY.INTL(OFFSET(hdr_PlanFinish,MATCH($J10,tsk_ID,0),0),IF(N($F10)=0,0,1)+N($L10),WorkWeek,Holidays),WORKDAY.INTL(OFFSET(hdr_PlanStart,MATCH($J10,tsk_ID,0),0),N($L10),WorkWeek,Holidays),WORKDAY.INTL(WORKDAY.INTL(OFFSET(hdr_PlanFinish,MATCH($J10,tsk_ID,0),0),N($L10),WorkWeek,Holidays),-MAX(0,N($F10)-1),WorkWeek,Holidays),WORKDAY.INTL(WORKDAY.INTL(OFFSET(hdr_PlanStart,MATCH($J10,tsk_ID,0),0),N($L10),WorkWeek,Holidays),-MAX(0,N($F10)-1),WorkWeek,Holidays)),0)) -> 0 | AM10: =IF(OR(N($G10)=0,$AI10,$D10=""),0,IFERROR(CHOOSE(MATCH(IF($H10="","FS",$H10),{"FS","SS","FF","SF"},0),WORKDAY.INTL(OFFSET(hdr_FcFinish,MATCH($G10,tsk_ID,0),0),IF(N($F10)=0,0,1)+N($I10),WorkWeek,Holidays),WORKDAY.INTL(OFFSET(hdr_FcStart,MATCH($G10,tsk_ID,0),0),N($I10),WorkWeek,Holidays),WORKDAY.INTL(WORKDAY.INTL(OFFSET(hdr_FcFinish,MATCH($G10,tsk_ID,0),0),N($I10),WorkWeek,Holidays),-MAX(0,N($F10)-1),WorkWeek,Holidays),WORKDAY.INTL(WORKDAY.INTL(OFFSET(hdr_FcStart,MATCH($G10,tsk_ID,0),0),N($I10),WorkWeek,Holidays),-MAX(0,N($F10)-1),WorkWeek,Holidays)),0)) -> 0 | AN10: =IF(OR(N($J10)=0,$AI10,$D10=""),0,IFERROR(CHOOSE(MATCH(IF($K10="","FS",$K10),{"FS","SS","FF","SF"},0),WORKDAY.INTL(OFFSET(hdr_FcFinish,MATCH($J10,tsk_ID,0),0),IF(N($F10)=0,0,1)+N($L10),WorkWeek,Holidays),WORKDAY.INTL(OFFSET(hdr_FcStart,MATCH($J10,tsk_ID,0),0),N($L10),WorkWeek,Holidays),WORKDAY.INTL(WORKDAY.INTL(OFFSET(hdr_FcFinish,MATCH($J10,tsk_ID,0),0),N($L10),WorkWeek,Holidays),-MAX(0,N($F10)-1),WorkWeek,Holidays),WORKDAY.INTL(WORKDAY.INTL(OFFSET(hdr_FcStart,MATCH($J10,tsk_ID,0),0),N($L10),WorkWeek,Holidays),-MAX(0,N($F10)-1),WorkWeek,Holidays)),0)) -> 0 | AO10: =IF($AJ10=1,$R10,0) -> 0 | AP10: =IF($AJ10=1,$S10,0) -> 0 | AQ10: =IF(AND($AJ10=1,N($Z10)>0),$Z10/($AP10-$AO10+1),0) -> 0 | AR10: =IF($AJ10=1,MAX(N($F10),0.1),0) -> 0 | AS10: =IF($AJ10=1,$AR10*$V10,0) -> 0 | AT10: =IF(N($G10)=0,"",$G10&IF(AND(IF($H10="","FS",$H10)="FS",N($I10)=0),"",IF($H10="","FS",$H10)&IF(N($I10)=0,"",IF(N($I10)>0,"+","")&N($I10)&"d"))) | AU10: =IF(N($J10)=0,"",$J10&IF(AND(IF($K10="","FS",$K10)="FS",N($L10)=0),"",IF($K10="","FS",$K10)&IF(N($L10)=0,"",IF(N($L10)>0,"+","")&N($L10)&"d"))) | AV10: =IF(AND($AJ10=1,N($F10)=0,$V10<1),$S10+$AF10/100000,"")
A11: =IF($D11="","",COUNTA($D$6:$D11)) -> 6 | B11: =IF($D11="","",IF($AE11=1,COUNTIF($AE$6:$AE11,1)&"",IF($AG11=0,"?",OFFSET(hdr_WBS,$AG11-ROW(hdr_WBS),0)&"."&COUNTIF(INDEX($AE:$AE,$AG11+1):$AE11,$AE11)))) -> 2.1 | C11: 2 | D11: Requirements gathering | E11: Auto | F11: 8 | G11: 4 | H11: FS | N11: =IF($D11="","",IF($AI11,MIN(OFFSET(hdr_PlanStart,$AF11+1,0,$AH11,1)),IF($E11="Manual",IF(N($M11)>0,$M11,ProjectStart),WORKDAY.INTL(MAX(ProjectStart,N($M11),$AK11,$AL11)-1,1,WorkWeek,Holidays)))) -> 46279 | O11: =IF($D11="","",IF($AI11,MAX(OFFSET(hdr_PlanFinish,$AF11+1,0,$AH11,1)),IF(N($F11)<=0,$N11,WORKDAY.INTL($N11,$F11-1,WorkWeek,Holidays)))) -> 46288 | P11: 46280 | Q11: 46290 | R11: =IF($D11="","",IF($AI11,MIN(OFFSET(hdr_FcStart,$AF11+1,0,$AH11,1)),IF(N($P11)>0,$P11,IF($E11="Manual",IF(N($M11)>0,$M11,ProjectStart),WORKDAY.INTL(MAX(ProjectStart,N($M11),$AM11,$AN11,IF(RescheduleAfterStatus="Yes",StatusDate,0))-1,1,WorkWeek,Holidays))))) -> 46280 | S11: =IF($D11="","",IF($AI11,MAX(OFFSET(hdr_FcFinish,$AF11+1,0,$AH11,1)),IF(N($Q11)>0,$Q11,IF(N($F11)<=0,$R11,IF(AND(N($P11)>0,RescheduleAfterStatus="Yes"),MAX(WORKDAY.INTL($R11,$F11-1,WorkWeek,Holidays),WORKDAY.INTL(StatusWorkday,MAX(0,ROUNDUP($F11*(1-MIN(1,N($U11))),0)-1),WorkWeek,Holidays)),WORKDAY.INTL($R11,$F11-1,WorkWeek,Holidays)))))) -> 46290 | T11: =IF($D11="","",IF($S11>=$O11,NETWORKDAYS.INTL($O11,$S11,WorkWeek,Holidays)-1,1-NETWORKDAYS.INTL($S11,$O11,WorkWeek,Holidays))) -> 2 | U11: 1 | V11: =IF($D11="","",IF($AI11,IFERROR(SUM(OFFSET(hdr_WtDone,$AF11+1,0,$AH11,1))/SUM(OFFSET(hdr_WtDur,$AF11+1,0,$AH11,1)),0),IF(N($Q11)>0,1,MIN(1,N($U11))))) -> 1 | W11: =IF($D11="","",IF($V11>=1,"Complete",IF(OR(N($P11)>0,$V11>0),IF($T11>0,"Behind","In Progress"),IF($N11<StatusDate,"Late Start","Not Started")))) -> Complete | X11: Morgan Patel | Z11: =IF($D11="","",IF($AI11,SUMPRODUCT(OFFSET(hdr_Work,$AF11+1,0,$AH11,1),OFFSET(hdr_IsLeaf,$AF11+1,0,$AH11,1)),IF($X11="",0,N($F11)*HoursPerDay*IF($Y11="",DefaultUnits,$Y11)))) -> 64 | AA11: =IF($D11="","",IF($AI11,SUMPRODUCT(OFFSET(hdr_Cost,$AF11+1,0,$AH11,1),OFFSET(hdr_IsLeaf,$AF11+1,0,$AH11,1)),$Z11*IFERROR(INDEX(res_Rate,MATCH($X11,res_Name,0)),0))) -> 4480 | AB11: =IF(OR($D11="",$AI11),"",IF(OR($R11<Sprint1Start,$R11>SprintLastEnd),"Backlog",INDEX(spr_Name,MATCH($R11,spr_Start,1)))) -> Sprint 1 | AC11: =IF($D11="","",$AT11&IF(AND($AT11<>"",$AU11<>""),",","")&$AU11) -> 4 | AE11: =IF($D11="","",MAX(1,N($C11))) -> 2 | AF11: =ROW()-ROW(hdr_ID) -> 6 | AG11: =IF(OR($D11="",$AE11<=1),0,IFERROR(LOOKUP(2,1/($AE$5:$AE10=$AE11-1),ROW($AE$5:$AE10)),0)) -> 10 | AH11: =IF($D11="",0,COUNTIF(tsk_WBS,$B11&".*")) -> 0 | AI11: =$AH11>0 -> FALSE | AJ11: =IF(AND($D11<>"",NOT($AI11)),1,0) -> 1 | AK11: =IF(OR(N($G11)=0,$AI11,$D11=""),0,IFERROR(CHOOSE(MATCH(IF($H11="","FS",$H11),{"FS","SS","FF","SF"},0),WORKDAY.INTL(OFFSET(hdr_PlanFinish,MATCH($G11,tsk_ID,0),0),IF(N($F11)=0,0,1)+N($I11),WorkWeek,Holidays),WORKDAY.INTL(OFFSET(hdr_PlanStart,MATCH($G11,tsk_ID,0),0),N($I11),WorkWeek,Holidays),WORKDAY.INTL(WORKDAY.INTL(OFFSET(hdr_PlanFinish,MATCH($G11,tsk_ID,0),0),N($I11),WorkWeek,Holidays),-MAX(0,N($F11)-1),WorkWeek,Holidays),WORKDAY.INTL(WORKDAY.INTL(OFFSET(hdr_PlanStart,MATCH($G11,tsk_ID,0),0),N($I11),WorkWeek,Holidays),-MAX(0,N($F11)-1),WorkWeek,Holidays)),0)) -> 46279 | AL11: =IF(OR(N($J11)=0,$AI11,$D11=""),0,IFERROR(CHOOSE(MATCH(IF($K11="","FS",$K11),{"FS","SS","FF","SF"},0),WORKDAY.INTL(OFFSET(hdr_PlanFinish,MATCH($J11,tsk_ID,0),0),IF(N($F11)=0,0,1)+N($L11),WorkWeek,Holidays),WORKDAY.INTL(OFFSET(hdr_PlanStart,MATCH($J11,tsk_ID,0),0),N($L11),WorkWeek,Holidays),WORKDAY.INTL(WORKDAY.INTL(OFFSET(hdr_PlanFinish,MATCH($J11,tsk_ID,0),0),N($L11),WorkWeek,Holidays),-MAX(0,N($F11)-1),WorkWeek,Holidays),WORKDAY.INTL(WORKDAY.INTL(OFFSET(hdr_PlanStart,MATCH($J11,tsk_ID,0),0),N($L11),WorkWeek,Holidays),-MAX(0,N($F11)-1),WorkWeek,Holidays)),0)) -> 0 | AM11: =IF(OR(N($G11)=0,$AI11,$D11=""),0,IFERROR(CHOOSE(MATCH(IF($H11="","FS",$H11),{"FS","SS","FF","SF"},0),WORKDAY.INTL(OFFSET(hdr_FcFinish,MATCH($G11,tsk_ID,0),0),IF(N($F11)=0,0,1)+N($I11),WorkWeek,Holidays),WORKDAY.INTL(OFFSET(hdr_FcStart,MATCH($G11,tsk_ID,0),0),N($I11),WorkWeek,Holidays),WORKDAY.INTL(WORKDAY.INTL(OFFSET(hdr_FcFinish,MATCH($G11,tsk_ID,0),0),N($I11),WorkWeek,Holidays),-MAX(0,N($F11)-1),WorkWeek,Holidays),WORKDAY.INTL(WORKDAY.INTL(OFFSET(hdr_FcStart,MATCH($G11,tsk_ID,0),0),N($I11),WorkWeek,Holidays),-MAX(0,N($F11)-1),WorkWeek,Holidays)),0)) -> 46280 | AN11: =IF(OR(N($J11)=0,$AI11,$D11=""),0,IFERROR(CHOOSE(MATCH(IF($K11="","FS",$K11),{"FS","SS","FF","SF"},0),WORKDAY.INTL(OFFSET(hdr_FcFinish,MATCH($J11,tsk_ID,0),0),IF(N($F11)=0,0,1)+N($L11),WorkWeek,Holidays),WORKDAY.INTL(OFFSET(hdr_FcStart,MATCH($J11,tsk_ID,0),0),N($L11),WorkWeek,Holidays),WORKDAY.INTL(WORKDAY.INTL(OFFSET(hdr_FcFinish,MATCH($J11,tsk_ID,0),0),N($L11),WorkWeek,Holidays),-MAX(0,N($F11)-1),WorkWeek,Holidays),WORKDAY.INTL(WORKDAY.INTL(OFFSET(hdr_FcStart,MATCH($J11,tsk_ID,0),0),N($L11),WorkWeek,Holidays),-MAX(0,N($F11)-1),WorkWeek,Holidays)),0)) -> 0 | AO11: =IF($AJ11=1,$R11,0) -> 46280 | AP11: =IF($AJ11=1,$S11,0) -> 46290 | AQ11: =IF(AND($AJ11=1,N($Z11)>0),$Z11/($AP11-$AO11+1),0) -> 5.8181818 | AR11: =IF($AJ11=1,MAX(N($F11),0.1),0) -> 8 | AS11: =IF($AJ11=1,$AR11*$V11,0) -> 8 | AT11: =IF(N($G11)=0,"",$G11&IF(AND(IF($H11="","FS",$H11)="FS",N($I11)=0),"",IF($H11="","FS",$H11)&IF(N($I11)=0,"",IF(N($I11)>0,"+","")&N($I11)&"d"))) -> 4 | AU11: =IF(N($J11)=0,"",$J11&IF(AND(IF($K11="","FS",$K11)="FS",N($L11)=0),"",IF($K11="","FS",$K11)&IF(N($L11)=0,"",IF(N($L11)>0,"+","")&N($L11)&"d"))) | AV11: =IF(AND($AJ11=1,N($F11)=0,$V11<1),$S11+$AF11/100000,"")
A12: =IF($D12="","",COUNTA($D$6:$D12)) -> 7 | B12: =IF($D12="","",IF($AE12=1,COUNTIF($AE$6:$AE12,1)&"",IF($AG12=0,"?",OFFSET(hdr_WBS,$AG12-ROW(hdr_WBS),0)&"."&COUNTIF(INDEX($AE:$AE,$AG12+1):$AE12,$AE12)))) -> 2.2 | C12: 2 | D12: Solution architecture | E12: Auto | F12: 5 | G12: 6 | H12: SS | I12: 3 | N12: =IF($D12="","",IF($AI12,MIN(OFFSET(hdr_PlanStart,$AF12+1,0,$AH12,1)),IF($E12="Manual",IF(N($M12)>0,$M12,ProjectStart),WORKDAY.INTL(MAX(ProjectStart,N($M12),$AK12,$AL12)-1,1,WorkWeek,Holidays)))) -> 46282 | O12: =IF($D12="","",IF($AI12,MAX(OFFSET(hdr_PlanFinish,$AF12+1,0,$AH12,1)),IF(N($F12)<=0,$N12,WORKDAY.INTL($N12,$F12-1,WorkWeek,Holidays)))) -> 46288 | P12: 46283 | Q12: 46290 | R12: =IF($D12="","",IF($AI12,MIN(OFFSET(hdr_FcStart,$AF12+1,0,$AH12,1)),IF(N($P12)>0,$P12,IF($E12="Manual",IF(N($M12)>0,$M12,ProjectStart),WORKDAY.INTL(MAX(ProjectStart,N($M12),$AM12,$AN12,IF(RescheduleAfterStatus="Yes",StatusDate,0))-1,1,WorkWeek,Holidays))))) -> 46283 | S12: =IF($D12="","",IF($AI12,MAX(OFFSET(hdr_FcFinish,$AF12+1,0,$AH12,1)),IF(N($Q12)>0,$Q12,IF(N($F12)<=0,$R12,IF(AND(N($P12)>0,RescheduleAfterStatus="Yes"),MAX(WORKDAY.INTL($R12,$F12-1,WorkWeek,Holidays),WORKDAY.INTL(StatusWorkday,MAX(0,ROUNDUP($F12*(1-MIN(1,N($U12))),0)-1),WorkWeek,Holidays)),WORKDAY.INTL($R12,$F12-1,WorkWeek,Holidays)))))) -> 46290 | T12: =IF($D12="","",IF($S12>=$O12,NETWORKDAYS.INTL($O12,$S12,WorkWeek,Holidays)-1,1-NETWORKDAYS.INTL($S12,$O12,WorkWeek,Holidays))) -> 2 | U12: 1 | V12: =IF($D12="","",IF($AI12,IFERROR(SUM(OFFSET(hdr_WtDone,$AF12+1,0,$AH12,1))/SUM(OFFSET(hdr_WtDur,$AF12+1,0,$AH12,1)),0),IF(N($Q12)>0,1,MIN(1,N($U12))))) -> 1 | W12: =IF($D12="","",IF($V12>=1,"Complete",IF(OR(N($P12)>0,$V12>0),IF($T12>0,"Behind","In Progress"),IF($N12<StatusDate,"Late Start","Not Started")))) -> Complete | X12: Alex Chen | Z12: =IF($D12="","",IF($AI12,SUMPRODUCT(OFFSET(hdr_Work,$AF12+1,0,$AH12,1),OFFSET(hdr_IsLeaf,$AF12+1,0,$AH12,1)),IF($X12="",0,N($F12)*HoursPerDay*IF($Y12="",DefaultUnits,$Y12)))) -> 40 | AA12: =IF($D12="","",IF($AI12,SUMPRODUCT(OFFSET(hdr_Cost,$AF12+1,0,$AH12,1),OFFSET(hdr_IsLeaf,$AF12+1,0,$AH12,1)),$Z12*IFERROR(INDEX(res_Rate,MATCH($X12,res_Name,0)),0))) -> 4400 | AB12: =IF(OR($D12="",$AI12),"",IF(OR($R12<Sprint1Start,$R12>SprintLastEnd),"Backlog",INDEX(spr_Name,MATCH($R12,spr_Start,1)))) -> Sprint 1 | AC12: =IF($D12="","",$AT12&IF(AND($AT12<>"",$AU12<>""),",","")&$AU12) -> 6SS+3d | AD12: Start-to-Start + 3 day lag example. | AE12: =IF($D12="","",MAX(1,N($C12))) -> 2 | AF12: =ROW()-ROW(hdr_ID) -> 7 | AG12: =IF(OR($D12="",$AE12<=1),0,IFERROR(LOOKUP(2,1/($AE$5:$AE11=$AE12-1),ROW($AE$5:$AE11)),0)) -> 10 | AH12: =IF($D12="",0,COUNTIF(tsk_WBS,$B12&".*")) -> 0 | AI12: =$AH12>0 -> FALSE | AJ12: =IF(AND($D12<>"",NOT($AI12)),1,0) -> 1 | AK12: =IF(OR(N($G12)=0,$AI12,$D12=""),0,IFERROR(CHOOSE(MATCH(IF($H12="","FS",$H12),{"FS","SS","FF","SF"},0),WORKDAY.INTL(OFFSET(hdr_PlanFinish,MATCH($G12,tsk_ID,0),0),IF(N($F12)=0,0,1)+N($I12),WorkWeek,Holidays),WORKDAY.INTL(OFFSET(hdr_PlanStart,MATCH($G12,tsk_ID,0),0),N($I12),WorkWeek,Holidays),WORKDAY.INTL(WORKDAY.INTL(OFFSET(hdr_PlanFinish,MATCH($G12,tsk_ID,0),0),N($I12),WorkWeek,Holidays),-MAX(0,N($F12)-1),WorkWeek,Holidays),WORKDAY.INTL(WORKDAY.INTL(OFFSET(hdr_PlanStart,MATCH($G12,tsk_ID,0),0),N($I12),WorkWeek,Holidays),-MAX(0,N($F12)-1),WorkWeek,Holidays)),0)) -> 46282 | AL12: =IF(OR(N($J12)=0,$AI12,$D12=""),0,IFERROR(CHOOSE(MATCH(IF($K12="","FS",$K12),{"FS","SS","FF","SF"},0),WORKDAY.INTL(OFFSET(hdr_PlanFinish,MATCH($J12,tsk_ID,0),0),IF(N($F12)=0,0,1)+N($L12),WorkWeek,Holidays),WORKDAY.INTL(OFFSET(hdr_PlanStart,MATCH($J12,tsk_ID,0),0),N($L12),WorkWeek,Holidays),WORKDAY.INTL(WORKDAY.INTL(OFFSET(hdr_PlanFinish,MATCH($J12,tsk_ID,0),0),N($L12),WorkWeek,Holidays),-MAX(0,N($F12)-1),WorkWeek,Holidays),WORKDAY.INTL(WORKDAY.INTL(OFFSET(hdr_PlanStart,MATCH($J12,tsk_ID,0),0),N($L12),WorkWeek,Holidays),-MAX(0,N($F12)-1),WorkWeek,Holidays)),0)) -> 0 | AM12: =IF(OR(N($G12)=0,$AI12,$D12=""),0,IFERROR(CHOOSE(MATCH(IF($H12="","FS",$H12),{"FS","SS","FF","SF"},0),WORKDAY.INTL(OFFSET(hdr_FcFinish,MATCH($G12,tsk_ID,0),0),IF(N($F12)=0,0,1)+N($I12),WorkWeek,Holidays),WORKDAY.INTL(OFFSET(hdr_FcStart,MATCH($G12,tsk_ID,0),0),N($I12),WorkWeek,Holidays),WORKDAY.INTL(WORKDAY.INTL(OFFSET(hdr_FcFinish,MATCH($G12,tsk_ID,0),0),N($I12),WorkWeek,Holidays),-MAX(0,N($F12)-1),WorkWeek,Holidays),WORKDAY.INTL(WORKDAY.INTL(OFFSET(hdr_FcStart,MATCH($G12,tsk_ID,0),0),N($I12),WorkWeek,Holidays),-MAX(0,N($F12)-1),WorkWeek,Holidays)),0)) -> 46283 | AN12: =IF(OR(N($J12)=0,$AI12,$D12=""),0,IFERROR(CHOOSE(MATCH(IF($K12="","FS",$K12),{"FS","SS","FF","SF"},0),WORKDAY.INTL(OFFSET(hdr_FcFinish,MATCH($J12,tsk_ID,0),0),IF(N($F12)=0,0,1)+N($L12),WorkWeek,Holidays),WORKDAY.INTL(OFFSET(hdr_FcStart,MATCH($J12,tsk_ID,0),0),N($L12),WorkWeek,Holidays),WORKDAY.INTL(WORKDAY.INTL(OFFSET(hdr_FcFinish,MATCH($J12,tsk_ID,0),0),N($L12),WorkWeek,Holidays),-MAX(0,N($F12)-1),WorkWeek,Holidays),WORKDAY.INTL(WORKDAY.INTL(OFFSET(hdr_FcStart,MATCH($J12,tsk_ID,0),0),N($L12),WorkWeek,Holidays),-MAX(0,N($F12)-1),WorkWeek,Holidays)),0)) -> 0 | AO12: =IF($AJ12=1,$R12,0) -> 46283 | AP12: =IF($AJ12=1,$S12,0) -> 46290 | AQ12: =IF(AND($AJ12=1,N($Z12)>0),$Z12/($AP12-$AO12+1),0) -> 5 | AR12: =IF($AJ12=1,MAX(N($F12),0.1),0) -> 5 | AS12: =IF($AJ12=1,$AR12*$V12,0) -> 5 | AT12: =IF(N($G12)=0,"",$G12&IF(AND(IF($H12="","FS",$H12)="FS",N($I12)=0),"",IF($H12="","FS",$H12)&IF(N($I12)=0,"",IF(N($I12)>0,"+","")&N($I12)&"d"))) -> 6SS+3d | AU12: =IF(N($J12)=0,"",$J12&IF(AND(IF($K12="","FS",$K12)="FS",N($L12)=0),"",IF($K12="","FS",$K12)&IF(N($L12)=0,"",IF(N($L12)>0,"+","")&N($L12)&"d"))) | AV12: =IF(AND($AJ12=1,N($F12)=0,$V12<1),$S12+$AF12/100000,"")
A13: =IF($D13="","",COUNTA($D$6:$D13)) -> 8 | B13: =IF($D13="","",IF($AE13=1,COUNTIF($AE$6:$AE13,1)&"",IF($AG13=0,"?",OFFSET(hdr_WBS,$AG13-ROW(hdr_WBS),0)&"."&COUNTIF(INDEX($AE:$AE,$AG13+1):$AE13,$AE13)))) -> 2.3 | C13: 2 | D13: UX wireframes & prototype | E13: Auto | F13: 6 | G13: 6 | H13: FS | N13: =IF($D13="","",IF($AI13,MIN(OFFSET(hdr_PlanStart,$AF13+1,0,$AH13,1)),IF($E13="Manual",IF(N($M13)>0,$M13,ProjectStart),WORKDAY.INTL(MAX(ProjectStart,N($M13),$AK13,$AL13)-1,1,WorkWeek,Holidays)))) -> 46289 | O13: =IF($D13="","",IF($AI13,MAX(OFFSET(hdr_PlanFinish,$AF13+1,0,$AH13,1)),IF(N($F13)<=0,$N13,WORKDAY.INTL($N13,$F13-1,WorkWeek,Holidays)))) -> 46296 | P13: 46293 | Q13: 46301 | R13: =IF($D13="","",IF($AI13,MIN(OFFSET(hdr_FcStart,$AF13+1,0,$AH13,1)),IF(N($P13)>0,$P13,IF($E13="Manual",IF(N($M13)>0,$M13,ProjectStart),WORKDAY.INTL(MAX(ProjectStart,N($M13),$AM13,$AN13,IF(RescheduleAfterStatus="Yes",StatusDate,0))-1,1,WorkWeek,Holidays))))) -> 46293 | S13: =IF($D13="","",IF($AI13,MAX(OFFSET(hdr_FcFinish,$AF13+1,0,$AH13,1)),IF(N($Q13)>0,$Q13,IF(N($F13)<=0,$R13,IF(AND(N($P13)>0,RescheduleAfterStatus="Yes"),MAX(WORKDAY.INTL($R13,$F13-1,WorkWeek,Holidays),WORKDAY.INTL(StatusWorkday,MAX(0,ROUNDUP($F13*(1-MIN(1,N($U13))),0)-1),WorkWeek,Holidays)),WORKDAY.INTL($R13,$F13-1,WorkWeek,Holidays)))))) -> 46301 | T13: =IF($D13="","",IF($S13>=$O13,NETWORKDAYS.INTL($O13,$S13,WorkWeek,Holidays)-1,1-NETWORKDAYS.INTL($S13,$O13,WorkWeek,Holidays))) -> 3 | U13: 1 | V13: =IF($D13="","",IF($AI13,IFERROR(SUM(OFFSET(hdr_WtDone,$AF13+1,0,$AH13,1))/SUM(OFFSET(hdr_WtDur,$AF13+1,0,$AH13,1)),0),IF(N($Q13)>0,1,MIN(1,N($U13))))) -> 1 | W13: =IF($D13="","",IF($V13>=1,"Complete",IF(OR(N($P13)>0,$V13>0),IF($T13>0,"Behind","In Progress"),IF($N13<StatusDate,"Late Start","Not Started")))) -> Complete | X13: Casey Kim | Z13: =IF($D13="","",IF($AI13,SUMPRODUCT(OFFSET(hdr_Work,$AF13+1,0,$AH13,1),OFFSET(hdr_IsLeaf,$AF13+1,0,$AH13,1)),IF($X13="",0,N($F13)*HoursPerDay*IF($Y13="",DefaultUnits,$Y13)))) -> 48 | AA13: =IF($D13="","",IF($AI13,SUMPRODUCT(OFFSET(hdr_Cost,$AF13+1,0,$AH13,1),OFFSET(hdr_IsLeaf,$AF13+1,0,$AH13,1)),$Z13*IFERROR(INDEX(res_Rate,MATCH($X13,res_Name,0)),0))) -> 3600 | AB13: =IF(OR($D13="",$AI13),"",IF(OR($R13<Sprint1Start,$R13>SprintLastEnd),"Backlog",INDEX(spr_Name,MATCH($R13,spr_Start,1)))) -> Sprint 2 | AC13: =IF($D13="","",$AT13&IF(AND($AT13<>"",$AU13<>""),",","")&$AU13) -> 6 | AE13: =IF($D13="","",MAX(1,N($C13))) -> 2 | AF13: =ROW()-ROW(hdr_ID) -> 8 | AG13: =IF(OR($D13="",$AE13<=1),0,IFERROR(LOOKUP(2,1/($AE$5:$AE12=$AE13-1),ROW($AE$5:$AE12)),0)) -> 10 | AH13: =IF($D13="",0,COUNTIF(tsk_WBS,$B13&".*")) -> 0 | AI13: =$AH13>0 -> FALSE | AJ13: =IF(AND($D13<>"",NOT($AI13)),1,0) -> 1 | AK13: =IF(OR(N($G13)=0,$AI13,$D13=""),0,IFERROR(CHOOSE(MATCH(IF($H13="","FS",$H13),{"FS","SS","FF","SF"},0),WORKDAY.INTL(OFFSET(hdr_PlanFinish,MATCH($G13,tsk_ID,0),0),IF(N($F13)=0,0,1)+N($I13),WorkWeek,Holidays),WORKDAY.INTL(OFFSET(hdr_PlanStart,MATCH($G13,tsk_ID,0),0),N($I13),WorkWeek,Holidays),WORKDAY.INTL(WORKDAY.INTL(OFFSET(hdr_PlanFinish,MATCH($G13,tsk_ID,0),0),N($I13),WorkWeek,Holidays),-MAX(0,N($F13)-1),WorkWeek,Holidays),WORKDAY.INTL(WORKDAY.INTL(OFFSET(hdr_PlanStart,MATCH($G13,tsk_ID,0),0),N($I13),WorkWeek,Holidays),-MAX(0,N($F13)-1),WorkWeek,Holidays)),0)) -> 46289 | AL13: =IF(OR(N($J13)=0,$AI13,$D13=""),0,IFERROR(CHOOSE(MATCH(IF($K13="","FS",$K13),{"FS","SS","FF","SF"},0),WORKDAY.INTL(OFFSET(hdr_PlanFinish,MATCH($J13,tsk_ID,0),0),IF(N($F13)=0,0,1)+N($L13),WorkWeek,Holidays),WORKDAY.INTL(OFFSET(hdr_PlanStart,MATCH($J13,tsk_ID,0),0),N($L13),WorkWeek,Holidays),WORKDAY.INTL(WORKDAY.INTL(OFFSET(hdr_PlanFinish,MATCH($J13,tsk_ID,0),0),N($L13),WorkWeek,Holidays),-MAX(0,N($F13)-1),WorkWeek,Holidays),WORKDAY.INTL(WORKDAY.INTL(OFFSET(hdr_PlanStart,MATCH($J13,tsk_ID,0),0),N($L13),WorkWeek,Holidays),-MAX(0,N($F13)-1),WorkWeek,Holidays)),0)) -> 0 | AM13: =IF(OR(N($G13)=0,$AI13,$D13=""),0,IFERROR(CHOOSE(MATCH(IF($H13="","FS",$H13),{"FS","SS","FF","SF"},0),WORKDAY.INTL(OFFSET(hdr_FcFinish,MATCH($G13,tsk_ID,0),0),IF(N($F13)=0,0,1)+N($I13),WorkWeek,Holidays),WORKDAY.INTL(OFFSET(hdr_FcStart,MATCH($G13,tsk_ID,0),0),N($I13),WorkWeek,Holidays),WORKDAY.INTL(WORKDAY.INTL(OFFSET(hdr_FcFinish,MATCH($G13,tsk_ID,0),0),N($I13),WorkWeek,Holidays),-MAX(0,N($F13)-1),WorkWeek,Holidays),WORKDAY.INTL(WORKDAY.INTL(OFFSET(hdr_FcStart,MATCH($G13,tsk_ID,0),0),N($I13),WorkWeek,Holidays),-MAX(0,N($F13)-1),WorkWeek,Holidays)),0)) -> 46293 | AN13: =IF(OR(N($J13)=0,$AI13,$D13=""),0,IFERROR(CHOOSE(MATCH(IF($K13="","FS",$K13),{"FS","SS","FF","SF"},0),WORKDAY.INTL(OFFSET(hdr_FcFinish,MATCH($J13,tsk_ID,0),0),IF(N($F13)=0,0,1)+N($L13),WorkWeek,Holidays),WORKDAY.INTL(OFFSET(hdr_FcStart,MATCH($J13,tsk_ID,0),0),N($L13),WorkWeek,Holidays),WORKDAY.INTL(WORKDAY.INTL(OFFSET(hdr_FcFinish,MATCH($J13,tsk_ID,0),0),N($L13),WorkWeek,Holidays),-MAX(0,N($F13)-1),WorkWeek,Holidays),WORKDAY.INTL(WORKDAY.INTL(OFFSET(hdr_FcStart,MATCH($J13,tsk_ID,0),0),N($L13),WorkWeek,Holidays),-MAX(0,N($F13)-1),WorkWeek,Holidays)),0)) -> 0 | AO13: =IF($AJ13=1,$R13,0) -> 46293 | AP13: =IF($AJ13=1,$S13,0) -> 46301 | AQ13: =IF(AND($AJ13=1,N($Z13)>0),$Z13/($AP13-$AO13+1),0) -> 5.3333333 | AR13: =IF($AJ13=1,MAX(N($F13),0.1),0) -> 6 | AS13: =IF($AJ13=1,$AR13*$V13,0) -> 6 | AT13: =IF(N($G13)=0,"",$G13&IF(AND(IF($H13="","FS",$H13)="FS",N($I13)=0),"",IF($H13="","FS",$H13)&IF(N($I13)=0,"",IF(N($I13)>0,"+","")&N($I13)&"d"))) -> 6 | AU13: =IF(N($J13)=0,"",$J13&IF(AND(IF($K13="","FS",$K13)="FS",N($L13)=0),"",IF($K13="","FS",$K13)&IF(N($L13)=0,"",IF(N($L13)>0,"+","")&N($L13)&"d"))) | AV13: =IF(AND($AJ13=1,N($F13)=0,$V13<1),$S13+$AF13/100000,"")
